08:08:03 PM:DEBUG [logger_base.py:13] Mensaje a nivel debug
08:08:03 PM:INFO [logger_base.py:14] Mensaje a nivel info
08:08:03 PM:WARNING [logger_base.py:15] Mensaje a nivel warning
08:08:03 PM:ERROR [logger_base.py:16] Mensaje a nivel error
08:08:03 PM:CRITICAL [logger_base.py:17] Mensaje a nivel critical
08:08:39 PM:DEBUG [logger_base.py:13] Mensaje a nivel debug
08:08:39 PM:INFO [logger_base.py:14] Mensaje a nivel info
08:08:39 PM:WARNING [logger_base.py:15] Mensaje a nivel warning
08:08:39 PM:ERROR [logger_base.py:16] Mensaje a nivel error
08:08:39 PM:CRITICAL [logger_base.py:17] Mensaje a nivel critical
08:08:49 PM:DEBUG [logger_base.py:13] Mensaje a nivel debug
08:08:49 PM:INFO [logger_base.py:14] Mensaje a nivel info
08:08:49 PM:WARNING [logger_base.py:15] Mensaje a nivel warning
08:08:49 PM:ERROR [logger_base.py:16] Mensaje a nivel error
08:08:49 PM:CRITICAL [logger_base.py:17] Mensaje a nivel critical
08:08:59 PM:DEBUG [logger_base.py:13] Mensaje a nivel debug
08:08:59 PM:INFO [logger_base.py:14] Mensaje a nivel info
08:08:59 PM:WARNING [logger_base.py:15] Mensaje a nivel warning
08:08:59 PM:ERROR [logger_base.py:16] Mensaje a nivel error
08:08:59 PM:CRITICAL [logger_base.py:17] Mensaje a nivel critical
08:10:21 PM:DEBUG [logger_base.py:13] Mensaje a nivel debug
08:10:21 PM:INFO [logger_base.py:14] Mensaje a nivel info
08:10:21 PM:WARNING [logger_base.py:15] Mensaje a nivel warning
08:10:21 PM:ERROR [logger_base.py:16] Mensaje a nivel error
08:10:21 PM:CRITICAL [logger_base.py:17] Mensaje a nivel critical
08:10:27 PM:DEBUG [Persona.py:55] 
            Id Persona: 1,
            Nombre: Juan,
            Apellido: Perez,
            Email: jperez@mail.com
        
08:10:27 PM:DEBUG [Persona.py:57] 
            Id Persona: None,
            Nombre: Jose,
            Apellido: Lepez,
            Email: ljose@mail.com
        
08:10:27 PM:DEBUG [Persona.py:59] 
            Id Persona: 1,
            Nombre: None,
            Apellido: None,
            Email: None
        
08:18:47 PM:ERROR [conexion.py:28] Ocurrió un error: connection to server at "127.0.0.1", port 5432 failed: Connection refused (0x0000274D/10061)
	Is the server running on that host and accepting TCP/IP connections?

08:22:04 PM:DEBUG [Persona.py:55] 
            Id Persona: 1,
            Nombre: Juan,
            Apellido: Perez,
            Email: jperez@mail.com
        
08:22:04 PM:DEBUG [Persona.py:57] 
            Id Persona: None,
            Nombre: Jose,
            Apellido: Lepez,
            Email: ljose@mail.com
        
08:22:04 PM:DEBUG [Persona.py:59] 
            Id Persona: 1,
            Nombre: None,
            Apellido: None,
            Email: None
        
08:22:36 PM:ERROR [conexion.py:28] Ocurrió un error: connection to server at "127.0.0.1", port 5432 failed: Connection refused (0x0000274D/10061)
	Is the server running on that host and accepting TCP/IP connections?

09:03:56 PM:ERROR [conexion.py:28] Ocurrió un error: connection to server at "127.0.0.1", port 5432 failed: Connection refused (0x0000274D/10061)
	Is the server running on that host and accepting TCP/IP connections?

09:04:33 PM:ERROR [conexion.py:28] Ocurrió un error: connection to server at "127.0.0.1", port 5432 failed: Connection refused (0x0000274D/10061)
	Is the server running on that host and accepting TCP/IP connections?

09:05:08 PM:ERROR [conexion.py:28] Ocurrió un error: connection to server at "127.0.0.1", port 5432 failed: Connection refused (0x0000274D/10061)
	Is the server running on that host and accepting TCP/IP connections?

09:07:12 PM:DEBUG [logger_base.py:13] Mensaje a nivel debug
09:07:12 PM:INFO [logger_base.py:14] Mensaje a nivel info
09:07:12 PM:WARNING [logger_base.py:15] Mensaje a nivel warning
09:07:12 PM:ERROR [logger_base.py:16] Mensaje a nivel error
09:07:12 PM:CRITICAL [logger_base.py:17] Mensaje a nivel critical
09:07:30 PM:DEBUG [logger_base.py:13] Mensaje a nivel debug
09:07:30 PM:INFO [logger_base.py:14] Mensaje a nivel info
09:07:30 PM:WARNING [logger_base.py:15] Mensaje a nivel warning
09:07:30 PM:ERROR [logger_base.py:16] Mensaje a nivel error
09:07:30 PM:CRITICAL [logger_base.py:17] Mensaje a nivel critical
09:07:54 PM:DEBUG [logger_base.py:13] Mensaje a nivel debug
09:07:54 PM:INFO [logger_base.py:14] Mensaje a nivel info
09:07:54 PM:WARNING [logger_base.py:15] Mensaje a nivel warning
09:07:54 PM:ERROR [logger_base.py:16] Mensaje a nivel error
09:07:54 PM:CRITICAL [logger_base.py:17] Mensaje a nivel critical
09:08:04 PM:ERROR [conexion.py:28] Ocurrió un error: connection to server at "127.0.0.1", port 5432 failed: Connection refused (0x0000274D/10061)
	Is the server running on that host and accepting TCP/IP connections?

09:33:43 PM:ERROR [conexion.py:28] Ocurrió un error: 'utf-8' codec can't decode byte 0xab in position 90: invalid start byte
01:52:25 PM:ERROR [conexion.py:28] Ocurrió un error: 'utf-8' codec can't decode byte 0xab in position 90: invalid start byte
02:48:59 PM:DEBUG [conexion.py:25] Conexión Exitosa: <connection object at 0x00000246D1A3B450; dsn: 'user=postgres password=xxx dbname=test_bd host=127.0.0.1 port=5432', closed: 0>
02:48:59 PM:DEBUG [conexion.py:38] Se abrió correctamente el cursor: <cursor object at 0x00000246D3697060; closed: 0>
